Workbook

Sheet Behovsmodell (75p)
A1: Behovsmodell – kohort på 75 personer / 30–35 hushåll
A2: Modellerad efterfrågan, INTE uppmätt data. Bygger på generella svenska konsumtionsgenomsnitt per åldersgrupp (uppskattade av Claude, ej källbelagda per produkt) och ett konsumtionsenhet-system (0,2 för småbarn upp till 1,0 för vuxna). Använd som utgångspunkt för samtal med producenter och för att stämma av mot en enkel medlemsenkät innan volymer avtalas.
A4: 1. Demografi & konsumtionsenheter (KE)
A5: Åldersgrupp | B5: Antal personer | C5: KE-koefficient | D5: Konsumtionsenheter (KE)
A6: 0–3 år | B6: 4 | C6: 0.2 | D6: =B6*C6 -> 0.8
A7: 4–10 år | B7: 9 | C7: 0.5 | D7: =B7*C7 -> 4.5
A8: 11–17 år | B8: 9 | C8: 0.75 | D8: =B8*C8 -> 6.75
A9: 18–64 år | B9: 45 | C9: 1 | D9: =B9*C9 -> 45
A10: 65+ år | B10: 8 | C10: 0.85 | D10: =B10*C10 -> 6.8
A11: Summa | B11: =SUM(B6:B10) -> 75 | D11: =SUM(D6:D10) -> 63.85
A14: 2. Kohortens uppskattade årsbehov per produkt
A15: Produkt-ID | B15: Kategori | C15: Produkt | D15: Enhet | E15: Antagen förbrukning/KE/år | F15: Kohort årsbehov (mängd) | G15: Kohort veckobehov (mängd) | H15: Matglädje mål (kr/enhet) | I15: Kohort årsvärde (kr) | J15: Kohort månadsvärde (kr) | K15: Årsvärde per person (kr) | L15: 0–3 år (mängd/år) | M15: 4–10 år (mängd/år) | N15: 11–17 år (mängd/år) | O15: 18–64 år (mängd/år) | P15: 65+ år (mängd/år)
A16: GRÖ-01 | B16: Grönsaker | C16: Potatis | D16: kr/kg | E16: 25 | F16: =E16*$D11 -> 1596.25 | G16: =F16/52 -> 30.697115 | H16: 20 | I16: =F16*H16 -> 31925 | J16: =I16/12 -> 2660.4167 | K16: =I16/$B$11 -> 425.66667 | L16: =$E16*$D$6 -> 20 | M16: =$E16*$D$7 -> 112.5 | N16: =$E16*$D$8 -> 168.75 | O16: =$E16*$D$9 -> 1125 | P16: =$E16*$D$10 -> 170
A17: GRÖ-02 | B17: Grönsaker | C17: Morot | D17: kr/kg | E17: 8 | F17: =E17*$D11 -> 510.8 | G17: =F17/52 -> 9.8230769 | H17: 20 | I17: =F17*H17 -> 10216 | J17: =I17/12 -> 851.33333 | K17: =I17/$B$11 -> 136.21333 | L17: =$E17*$D$6 -> 6.4 | M17: =$E17*$D$7 -> 36 | N17: =$E17*$D$8 -> 54 | O17: =$E17*$D$9 -> 360 | P17: =$E17*$D$10 -> 54.4
A18: GRÖ-03 | B18: Grönsaker | C18: Gul lök | D18: kr/kg | E18: 6 | F18: =E18*$D11 -> 383.1 | G18: =F18/52 -> 7.3673077 | H18: 20 | I18: =F18*H18 -> 7662 | J18: =I18/12 -> 638.5 | K18: =I18/$B$11 -> 102.16 | L18: =$E18*$D$6 -> 4.8 | M18: =$E18*$D$7 -> 27 | N18: =$E18*$D$8 -> 40.5 | O18: =$E18*$D$9 -> 270 | P18: =$E18*$D$10 -> 40.8
A19: GRÖ-04 | B19: Grönsaker | C19: Vitkål | D19: kr/kg | E19: 4 | F19: =E19*$D11 -> 255.4 | G19: =F19/52 -> 4.9115385 | H19: 15 | I19: =F19*H19 -> 3831 | J19: =I19/12 -> 319.25 | K19: =I19/$B$11 -> 51.08 | L19: =$E19*$D$6 -> 3.2 | M19: =$E19*$D$7 -> 18 | N19: =$E19*$D$8 -> 27 | O19: =$E19*$D$9 -> 180 | P19: =$E19*$D$10 -> 27.2
A20: GRÖ-05 | B20: Grönsaker | C20: Tomat, växthus | D20: kr/kg | E20: 10 | F20: =E20*$D11 -> 638.5 | G20: =F20/52 -> 12.278846 | H20: 50 | I20: =F20*H20 -> 31925 | J20: =I20/12 -> 2660.4167 | K20: =I20/$B$11 -> 425.66667 | L20: =$E20*$D$6 -> 8 | M20: =$E20*$D$7 -> 45 | N20: =$E20*$D$8 -> 67.5 | O20: =$E20*$D$9 -> 450 | P20: =$E20*$D$10 -> 68
A21: FRU-01 | B21: Frukt & bär | C21: Äpple | D21: kr/kg | E21: 12 | F21: =E21*$D11 -> 766.2 | G21: =F21/52 -> 14.734615 | H21: 27 | I21: =F21*H21 -> 20687.4 | J21: =I21/12 -> 1723.95 | K21: =I21/$B$11 -> 275.832 | L21: =$E21*$D$6 -> 9.6 | M21: =$E21*$D$7 -> 54 | N21: =$E21*$D$8 -> 81 | O21: =$E21*$D$9 -> 540 | P21: =$E21*$D$10 -> 81.6
A22: FRU-02 | B22: Frukt & bär | C22: Päron | D22: kr/kg | E22: 3 | F22: =E22*$D11 -> 191.55 | G22: =F22/52 -> 3.6836538 | H22: 29 | I22: =F22*H22 -> 5554.95 | J22: =I22/12 -> 462.9125 | K22: =I22/$B$11 -> 74.066 | L22: =$E22*$D$6 -> 2.4 | M22: =$E22*$D$7 -> 13.5 | N22: =$E22*$D$8 -> 20.25 | O22: =$E22*$D$9 -> 135 | P22: =$E22*$D$10 -> 20.4
A23: FRU-03 | B23: Frukt & bär | C23: Jordgubbar | D23: kr/kg | E23: 3 | F23: =E23*$D11 -> 191.55 | G23: =F23/52 -> 3.6836538 | H23: 77 | I23: =F23*H23 -> 14749.35 | J23: =I23/12 -> 1229.1125 | K23: =I23/$B$11 -> 196.658 | L23: =$E23*$D$6 -> 2.4 | M23: =$E23*$D$7 -> 13.5 | N23: =$E23*$D$8 -> 20.25 | O23: =$E23*$D$9 -> 135 | P23: =$E23*$D$10 -> 20.4
A24: FRU-04 | B24: Frukt & bär | C24: Blåbär | D24: kr/kg | E24: 1.5 | F24: =E24*$D11 -> 95.775 | G24: =F24/52 -> 1.8418269 | H24: 54 | I24: =F24*H24 -> 5171.85 | J24: =I24/12 -> 430.9875 | K24: =I24/$B$11 -> 68.958 | L24: =$E24*$D$6 -> 1.2 | M24: =$E24*$D$7 -> 6.75 | N24: =$E24*$D$8 -> 10.125 | O24: =$E24*$D$9 -> 67.5 | P24: =$E24*$D$10 -> 10.2
A25: BAL-01 | B25: Baljväxter | C25: Gula ärtor | D25: kr/kg | E25: 1 | F25: =E25*$D11 -> 63.85 | G25: =F25/52 -> 1.2278846 | H25: 33 | I25: =F25*H25 -> 2107.05 | J25: =I25/12 -> 175.5875 | K25: =I25/$B$11 -> 28.094 | L25: =$E25*$D$6 -> 0.8 | M25: =$E25*$D$7 -> 4.5 | N25: =$E25*$D$8 -> 6.75 | O25: =$E25*$D$9 -> 45 | P25: =$E25*$D$10 -> 6.8
A26: BAL-02 | B26: Baljväxter | C26: Bruna bönor | D26: kr/kg | E26: 1 | F26: =E26*$D11 -> 63.85 | G26: =F26/52 -> 1.2278846 | H26: 45 | I26: =F26*H26 -> 2873.25 | J26: =I26/12 -> 239.4375 | K26: =I26/$B$11 -> 38.31 | L26: =$E26*$D$6 -> 0.8 | M26: =$E26*$D$7 -> 4.5 | N26: =$E26*$D$8 -> 6.75 | O26: =$E26*$D$9 -> 45 | P26: =$E26*$D$10 -> 6.8
A27: BAL-03 | B27: Baljväxter | C27: Åkerböna | D27: kr/kg | E27: 0.5 | F27: =E27*$D11 -> 31.925 | G27: =F27/52 -> 0.61394231 | H27: 38 | I27: =F27*H27 -> 1213.15 | J27: =I27/12 -> 101.09583 | K27: =I27/$B$11 -> 16.175333 | L27: =$E27*$D$6 -> 0.4 | M27: =$E27*$D$7 -> 2.25 | N27: =$E27*$D$8 -> 3.375 | O27: =$E27*$D$9 -> 22.5 | P27: =$E27*$D$10 -> 3.4
A28: SPA-01 | B28: Spannmål | C28: Havregryn | D28: kr/kg | E28: 8 | F28: =E28*$D11 -> 510.8 | G28: =F28/52 -> 9.8230769 | H28: 31 | I28: =F28*H28 -> 15834.8 | J28: =I28/12 -> 1319.5667 | K28: =I28/$B$11 -> 211.13067 | L28: =$E28*$D$6 -> 6.4 | M28: =$E28*$D$7 -> 36 | N28: =$E28*$D$8 -> 54 | O28: =$E28*$D$9 -> 360 | P28: =$E28*$D$10 -> 54.4
A29: SPA-02 | B29: Spannmål | C29: Rågmjöl | D29: kr/kg | E29: 3 | F29: =E29*$D11 -> 191.55 | G29: =F29/52 -> 3.6836538 | H29: 27 | I29: =F29*H29 -> 5171.85 | J29: =I29/12 -> 430.9875 | K29: =I29/$B$11 -> 68.958 | L29: =$E29*$D$6 -> 2.4 | M29: =$E29*$D$7 -> 13.5 | N29: =$E29*$D$8 -> 20.25 | O29: =$E29*$D$9 -> 135 | P29: =$E29*$D$10 -> 20.4
A30: SPA-03 | B30: Spannmål | C30: Vetemjöl | D30: kr/kg | E30: 10 | F30: =E30*$D11 -> 638.5 | G30: =F30/52 -> 12.278846 | H30: 22 | I30: =F30*H30 -> 14047 | J30: =I30/12 -> 1170.5833 | K30: =I30/$B$11 -> 187.29333 | L30: =$E30*$D$6 -> 8 | M30: =$E30*$D$7 -> 45 | N30: =$E30*$D$8 -> 67.5 | O30: =$E30*$D$9 -> 450 | P30: =$E30*$D$10 -> 68
A31: SPA-04 | B31: Spannmål | C31: Korngryn | D31: kr/kg | E31: 1 | F31: =E31*$D11 -> 63.85 | G31: =F31/52 -> 1.2278846 | H31: 22 | I31: =F31*H31 -> 1404.7 | J31: =I31/12 -> 117.05833 | K31: =I31/$B$11 -> 18.729333 | L31: =$E31*$D$6 -> 0.8 | M31: =$E31*$D$7 -> 4.5 | N31: =$E31*$D$8 -> 6.75 | O31: =$E31*$D$9 -> 45 | P31: =$E31*$D$10 -> 6.8
A32: KÖT-01 | B32: Kött | C32: Nötfärs | D32: kr/kg | E32: 8 | F32: =E32*$D11 -> 510.8 | G32: =F32/52 -> 9.8230769 | H32: 108 | I32: =F32*H32 -> 55166.4 | J32: =I32/12 -> 4597.2 | K32: =I32/$B$11 -> 735.552 | L32: =$E32*$D$6 -> 6.4 | M32: =$E32*$D$7 -> 36 | N32: =$E32*$D$8 -> 54 | O32: =$E32*$D$9 -> 360 | P32: =$E32*$D$10 -> 54.4
A33: KÖT-02 | B33: Kött | C33: Fläskkotlett | D33: kr/kg | E33: 6 | F33: =E33*$D11 -> 383.1 | G33: =F33/52 -> 7.3673077 | H33: 113 | I33: =F33*H33 -> 43290.3 | J33: =I33/12 -> 3607.525 | K33: =I33/$B$11 -> 577.204 | L33: =$E33*$D$6 -> 4.8 | M33: =$E33*$D$7 -> 27 | N33: =$E33*$D$8 -> 40.5 | O33: =$E33*$D$9 -> 270 | P33: =$E33*$D$10 -> 40.8
A34: KÖT-03 | B34: Kött | C34: Kycklingfilé | D34: kr/kg | E34: 10 | F34: =E34*$D11 -> 638.5 | G34: =F34/52 -> 12.278846 | H34: 140 | I34: =F34*H34 -> 89390 | J34: =I34/12 -> 7449.1667 | K34: =I34/$B$11 -> 1191.8667 | L34: =$E34*$D$6 -> 8 | M34: =$E34*$D$7 -> 45 | N34: =$E34*$D$8 -> 67.5 | O34: =$E34*$D$9 -> 450 | P34: =$E34*$D$10 -> 68
A35: KÖT-04 | B35: Kött | C35: Lammkött | D35: kr/kg | E35: 1.5 | F35: =E35*$D11 -> 95.775 | G35: =F35/52 -> 1.8418269 | H35: 194 | I35: =F35*H35 -> 18580.35 | J35: =I35/12 -> 1548.3625 | K35: =I35/$B$11 -> 247.738 | L35: =$E35*$D$6 -> 1.2 | M35: =$E35*$D$7 -> 6.75 | N35: =$E35*$D$8 -> 10.125 | O35: =$E35*$D$9 -> 67.5 | P35: =$E35*$D$10 -> 10.2
A36: FIS-01 | B36: Fisk | C36: Odlad lax/regnbåge | D36: kr/kg | E36: 4 | F36: =E36*$D11 -> 255.4 | G36: =F36/52 -> 4.9115385 | H36: 158 | I36: =F36*H36 -> 40353.2 | J36: =I36/12 -> 3362.7667 | K36: =I36/$B$11 -> 538.04267 | L36: =$E36*$D$6 -> 3.2 | M36: =$E36*$D$7 -> 18 | N36: =$E36*$D$8 -> 27 | O36: =$E36*$D$9 -> 180 | P36: =$E36*$D$10 -> 27.2
A37: FIS-02 | B37: Fisk | C37: Strömming/sill | D37: kr/kg | E37: 2 | F37: =E37*$D11 -> 127.7 | G37: =F37/52 -> 2.4557692 | H37: 50 | I37: =F37*H37 -> 6385 | J37: =I37/12 -> 532.08333 | K37: =I37/$B$11 -> 85.133333 | L37: =$E37*$D$6 -> 1.6 | M37: =$E37*$D$7 -> 9 | N37: =$E37*$D$8 -> 13.5 | O37: =$E37*$D$9 -> 90 | P37: =$E37*$D$10 -> 13.6
A38: FIS-03 | B38: Fisk | C38: Gös/abborre | D38: kr/kg | E38: 1 | F38: =E38*$D11 -> 63.85 | G38: =F38/52 -> 1.2278846 | H38: 180 | I38: =F38*H38 -> 11493 | J38: =I38/12 -> 957.75 | K38: =I38/$B$11 -> 153.24 | L38: =$E38*$D$6 -> 0.8 | M38: =$E38*$D$7 -> 4.5 | N38: =$E38*$D$8 -> 6.75 | O38: =$E38*$D$9 -> 45 | P38: =$E38*$D$10 -> 6.8
A39: MEJ-01 | B39: Mejeri & ägg | C39: Mjölk | D39: kr/l | E39: 60 | F39: =E39*$D11 -> 3831 | G39: =F39/52 -> 73.673077 | H39: 19 | I39: =F39*H39 -> 72789 | J39: =I39/12 -> 6065.75 | K39: =I39/$B$11 -> 970.52 | L39: =$E39*$D$6 -> 48 | M39: =$E39*$D$7 -> 270 | N39: =$E39*$D$8 -> 405 | O39: =$E39*$D$9 -> 2700 | P39: =$E39*$D$10 -> 408
A40: MEJ-02 | B40: Mejeri & ägg | C40: Smör | D40: kr/kg | E40: 3 | F40: =E40*$D11 -> 191.55 | G40: =F40/52 -> 3.6836538 | H40: 158 | I40: =F40*H40 -> 30264.9 | J40: =I40/12 -> 2522.075 | K40: =I40/$B$11 -> 403.532 | L40: =$E40*$D$6 -> 2.4 | M40: =$E40*$D$7 -> 13.5 | N40: =$E40*$D$8 -> 20.25 | O40: =$E40*$D$9 -> 135 | P40: =$E40*$D$10 -> 20.4
A41: MEJ-03 | B41: Mejeri & ägg | C41: Ägg | D41: kr/förp | E41: 25 | F41: =E41*$D11 -> 1596.25 | G41: =F41/52 -> 30.697115 | H41: 42 | I41: =F41*H41 -> 67042.5 | J41: =I41/12 -> 5586.875 | K41: =I41/$B$11 -> 893.9 | L41: =$E41*$D$6 -> 20 | M41: =$E41*$D$7 -> 112.5 | N41: =$E41*$D$8 -> 168.75 | O41: =$E41*$D$9 -> 1125 | P41: =$E41*$D$10 -> 170
A42: MEJ-04 | B42: Mejeri & ägg | C42: Hushållsost | D42: kr/kg | E42: 15 | F42: =E42*$D11 -> 957.75 | G42: =F42/52 -> 18.418269 | H42: 167 | I42: =F42*H42 -> 159944.25 | J42: =I42/12 -> 13328.688 | K42: =I42/$B$11 -> 2132.59 | L42: =$E42*$D$6 -> 12 | M42: =$E42*$D$7 -> 67.5 | N42: =$E42*$D$8 -> 101.25 | O42: =$E42*$D$9 -> 675 | P42: =$E42*$D$10 -> 102
A43: NÖT-01 | B43: Nötter | C43: Valnötter | D43: kr/kg | E43: 1 | F43: =E43*$D11 -> 63.85 | G43: =F43/52 -> 1.2278846 | H43: 155 | I43: =F43*H43 -> 9896.75 | J43: =I43/12 -> 824.72917 | K43: =I43/$B$11 -> 131.95667 | L43: =$E43*$D$6 -> 0.8 | M43: =$E43*$D$7 -> 4.5 | N43: =$E43*$D$8 -> 6.75 | O43: =$E43*$D$9 -> 45 | P43: =$E43*$D$10 -> 6.8
...

Sheet Läs mig
A1: Matglädje – skafferi & underlag
A2: Arbetsdokument, byggt stegvis. Skafferi-bladet är ifyllt; övriga blad är mallar.
A5: Struktur
A6: Skafferi | B6: Kategori, produkt och prisjämförelse (Butik / Ekobutik / REKO / Matglädje-mål). Grunden alla andra blad länkar till via Produkt-ID.
A7: Producenter | B7: Mall – vilken producent som levererar respektive produkt.
A8: Recept | B8: Mall – recept kopplade till skafferiets produkter.
A9: Hemfabrikat | B9: Mall – råvaror som blir till nya basvaror (t.ex. havre till havremjölk).
A10: Om grödan | B10: Mall – säsong, ursprung och kort fakta per produkt.
A12: Produkt-ID | B12: Kategori-kod + löpnummer, t.ex. GRÖ-01. Används som nyckel mellan alla blad.
A14: Prissäkerhet (Skafferi-bladet)
A15: Verifierat | B15: Minst ett av priserna är grundat i faktisk sökning (t.ex. ICA-pris, REKO-rapport, biodlarpris).
A16: Uppskattat (mönster) | B16: Inget pris sökt specifikt för raden – bygger på det mönster som identifierats för kategorin (REKO/eko generellt dyrare för hantverksmejeri och kött, jämförbart för rotfrukt, etc). Behandla som riktning, inte exakt siffra.
A18: Matglädje-kolumnen | B18: Målnivå (hypotes), inte uppmätt pris. Bygger på resonemanget att Matglädje är billigare att sälja till än en enskild REKO-kund (färre transaktioner, ingen marknadsföring, betalningssäkerhet) – cirka 5-15% under REKO för lokalt sourcebara varor.
A20: Färgkod i mallbladen
A21: Ljusgul rad | B21: Exempelrad – visar förväntat format. Ersätt eller komplettera med riktiga rader.
A24: Producenter-bladet
A25: Grön rad – 'Kandidat identifierad' | B25: Ett namngivet, verkligt företag hittat via sökning. Inte kontaktat eller bekräftat av Matglädje – ren research, inte en relation.
A26: Grå rad – 'Ingen specifik kandidat' | B26: Ingen enskild producent verifierad än. Kolumnen Källa pekar på en sökbar katalog (t.ex. gardsnara.se, gardsbutiker.se) att gå vidare på själv.
A27: Grå rad – 'Ej relevant' | B27: Ren importvara (t.ex. valnötter, olivolja) – ingen svensk direktkälla att leta efter.
A28: Viktigt | B28: Ingen av kandidaterna är kontaktad eller har tackat ja. Detta är en researchlista att jobba vidare på, inte bekräftade leverantörer.
A30: Gårdsguiden – kandidater
A31: 993 rader skrapade från gardsguiden.se/gardar (2026-08-16). Namn/ort/län/kategori/öppettider extraherat ur sidans textlista med ett Python-skript (regex-baserad tolkning, inte en officiell API/export). ~18 rader är flaggade i kolumnen "Granska" där tolkningen är osäker (t.ex. gårdsnamn som innehåller ett länsnamn, vilket kan lura parsern) – kontrollera dessa manuellt. Kategorikolumnen "Skafferi-kategori" är en grov koppling mellan Gårdsguidens taggar och Skafferi-fliken's kategorier (t.ex. "kött"->Kött, "grönsaker"->Grönsaker) – det är INTE en koppling till enskilda Produkt-ID, eftersom Gårdsguiden inte anger vilka specifika produkter (t.ex. potatis vs morot) en gård säljer. Använd fliken som en kandidatlista att korsa mot Producenter-fliken när ni letar leverantör per kategori.
A33: Kontaktberikade producenter
A34: 288 producenter/gårdar berikade med webb/telefon/e-post/adress (2026-08-18) via research över öppna källor (KRAV:s gårdsbutiksguide, gardsbutiker-skane.se, regionala matnätverk som MAT-rundan Kronoberg, Sörmlands Matkluster, Smaka på Västmanland, Fjärdhundraland, Visit Halland/Blekinge/Gotland/Öland, bolagsregister m.fl. - inte gardsguiden.se, som blockerar automatiserad åtkomst). Se ny flik "Kontaktberikade producenter" för hela listan. Av dessa har 162 kunnat matchas mot befintliga rader i "Gårdsguiden – kandidater" (kolumnerna Webb/Telefon/Epost/Adress (berikad) längst till höger där); resten är nya poster utanför den ursprungliga skrapningen (t.ex. hittade via regionala kataloger). Kontrollera "Anmärkning"-kolumnen: några poster är flaggade som ej primärproducenter, har motstridiga uppgifter, eller avkortade telefonnummer som bör verifieras innan utskick.

Sheet Producenter
A1: Produkt-ID | B1: Produkt (auto) | C1: Producent/kandidat | D1: Region | E1: Webb/kontakt | F1: Leveranssätt (enl. hemsida) | G1: Status | H1: Källa
A2: GRÖ-01 | B2: =IFERROR(INDEX(Skafferi!$C$2:$C$43,MATCH(A2,Skafferi!$A$2:$A$43,0)),"") -> Potatis | C2: Everhags Gårdsbutik | D2: Vedum, Västergötland | E2: everhagsgardsbutik.se | F2: Gårdsbutik, självbetjäning, alltid öppet | G2: Kandidat identifierad – ej kontaktad | H2: KRAV:s gårdsbutiksguide
A3: GRÖ-02 | B3: =IFERROR(INDEX(Skafferi!$C$2:$C$43,MATCH(A3,Skafferi!$A$2:$A$43,0)),"") -> Morot | C3: Gröna Gårdar AB | D3: Ljungskile, Bohuslän | E3: - | F3: Gårdsbutik tis-lör | G3: Kandidat identifierad – ej kontaktad | H3: KRAV:s gårdsbutiksguide (säsongsgrönt, ospecificerat sortiment)
A4: GRÖ-03 | B4: =IFERROR(INDEX(Skafferi!$C$2:$C$43,MATCH(A4,Skafferi!$A$2:$A$43,0)),"") -> Gul lök | C4: Gröna Gårdar AB | D4: Ljungskile, Bohuslän | E4: - | F4: Gårdsbutik tis-lör | G4: Kandidat identifierad – ej kontaktad | H4: KRAV:s gårdsbutiksguide (säsongsgrönt, ospecificerat sortiment)
A5: GRÖ-04 | B5: =IFERROR(INDEX(Skafferi!$C$2:$C$43,MATCH(A5,Skafferi!$A$2:$A$43,0)),"") -> Vitkål | C5: Gröna Gårdar AB | D5: Ljungskile, Bohuslän | E5: - | F5: Gårdsbutik tis-lör | G5: Kandidat identifierad – ej kontaktad | H5: KRAV:s gårdsbutiksguide (säsongsgrönt, ospecificerat sortiment)
A6: GRÖ-05 | B6: =IFERROR(INDEX(Skafferi!$C$2:$C$43,MATCH(A6,Skafferi!$A$2:$A$43,0)),"") -> Tomat, växthus | C6: - | D6: - | E6: - | F6: - | G6: Ingen specifik kandidat – sök via källa | H6: Sök gardsnara.se, filter Frukt och grönt > Tomat, region efter val
A7: FRU-01 | B7: =IFERROR(INDEX(Skafferi!$C$2:$C$43,MATCH(A7,Skafferi!$A$2:$A$43,0)),"") -> Äpple | C7: - | D7: - | E7: - | F7: - | G7: Ingen specifik kandidat – sök via källa | H7: Sök gardsnara.se / gardsbutiker.se, kategori Frukt och grönt
A8: FRU-02 | B8: =IFERROR(INDEX(Skafferi!$C$2:$C$43,MATCH(A8,Skafferi!$A$2:$A$43,0)),"") -> Päron | C8: - | D8: - | E8: - | F8: - | G8: Ingen specifik kandidat – sök via källa | H8: Sök gardsnara.se / gardsbutiker.se, kategori Frukt och grönt
A9: FRU-03 | B9: =IFERROR(INDEX(Skafferi!$C$2:$C$43,MATCH(A9,Skafferi!$A$2:$A$43,0)),"") -> Jordgubbar | C9: - | D9: - | E9: - | F9: - | G9: Ingen specifik kandidat – sök via källa | H9: Sök gardsnara.se / gardsbutiker.se, kategori Frukt och grönt (självplock vanligt)
A10: FRU-04 | B10: =IFERROR(INDEX(Skafferi!$C$2:$C$43,MATCH(A10,Skafferi!$A$2:$A$43,0)),"") -> Blåbär | C10: - | D10: - | E10: - | F10: - | G10: Ingen specifik kandidat – sök via källa | H10: Sök gardsnara.se, eller lokal bärplockare/naturbruksskola för vilda bär
A11: BAL-01 | B11: =IFERROR(INDEX(Skafferi!$C$2:$C$43,MATCH(A11,Skafferi!$A$2:$A$43,0)),"") -> Gula ärtor | C11: - | D11: - | E11: - | F11: - | G11: Ingen specifik kandidat – sök via källa | H11: Sök matvision.se / gardsnara.se, kategori Bröd och spannmål (baljväxter ofta samodlat)
A12: BAL-02 | B12: =IFERROR(INDEX(Skafferi!$C$2:$C$43,MATCH(A12,Skafferi!$A$2:$A$43,0)),"") -> Bruna bönor | C12: - | D12: - | E12: - | F12: - | G12: Ingen specifik kandidat – sök via källa | H12: Sök matvision.se / gardsnara.se, kategori Bröd och spannmål
A13: BAL-03 | B13: =IFERROR(INDEX(Skafferi!$C$2:$C$43,MATCH(A13,Skafferi!$A$2:$A$43,0)),"") -> Åkerböna | C13: - | D13: - | E13: - | F13: - | G13: Ingen specifik kandidat – sök via källa | H13: Sök matvision.se / gardsnara.se, kategori Bröd och spannmål (nischodling, växande)
... A43: BRÖ-02 | B43: =IFERROR(INDEX(Skafferi!$C$2:$C$43,MATCH(A43,Skafferi!$A$2:$A$43,0)),"") -> Knäckebröd/rågbröd | C43: - | D43: - | E43: - | F43: - | G43: Ingen specifik kandidat – sök via källa | H43: Sök gardsnara.se / matvision.se, kategori Bröd och spannmål, filtrera kvarn/bageri

Sheet Skafferi
A1: Produkt-ID | B1: Kategori | C1: Produkt | D1: Enhet | E1: Butik (kr) | F1: Ekobutik (kr) | G1: REKO (kr) | H1: Matglädje mål (kr) | I1: vs Butik (%) | J1: vs REKO (%) | K1: Säkerhet | L1: Kommentar
A2: GRÖ-01 | B2: Grönsaker | C2: Potatis | D2: kr/kg | E2: 24 | F2: 31 | G2: 22 | H2: 20 | I2: =IFERROR((H2-E2)/E2,"") -> -0.16666667 | J2: =IFERROR((H2-G2)/G2,"") -> -0.090909091 | K2: Verifierat
A3: GRÖ-02 | B3: Grönsaker | C3: Morot | D3: kr/kg | E3: 20 | F3: 26 | G3: 22 | H3: 20 | I3: =IFERROR((H3-E3)/E3,"") -> 0 | J3: =IFERROR((H3-G3)/G3,"") -> -0.090909091 | K3: Uppskattat (mönster)
A4: GRÖ-03 | B4: Grönsaker | C4: Gul lök | D4: kr/kg | E4: 21 | F4: 27 | G4: 22 | H4: 20 | I4: =IFERROR((H4-E4)/E4,"") -> -0.047619048 | J4: =IFERROR((H4-G4)/G4,"") -> -0.090909091 | K4: Uppskattat (mönster)
A5: GRÖ-04 | B5: Grönsaker | C5: Vitkål | D5: kr/kg | E5: 15 | F5: 20 | G5: 17 | H5: 15 | I5: =IFERROR((H5-E5)/E5,"") -> 0 | J5: =IFERROR((H5-G5)/G5,"") -> -0.11764706 | K5: Uppskattat (mönster)
A6: GRÖ-05 | B6: Grönsaker | C6: Tomat, växthus | D6: kr/kg | E6: 45 | F6: 60 | G6: 55 | H6: 50 | I6: =IFERROR((H6-E6)/E6,"") -> 0.11111111 | J6: =IFERROR((H6-G6)/G6,"") -> -0.090909091 | K6: Uppskattat (mönster) | L6: Växthusodling kostar oavsett kanal
A7: FRU-01 | B7: Frukt & bär | C7: Äpple | D7: kr/kg | E7: 30 | F7: 40 | G7: 30 | H7: 27 | I7: =IFERROR((H7-E7)/E7,"") -> -0.1 | J7: =IFERROR((H7-G7)/G7,"") -> -0.1 | K7: Uppskattat (mönster) | L7: Säsong
A8: FRU-02 | B8: Frukt & bär | C8: Päron | D8: kr/kg | E8: 32 | F8: 42 | G8: 32 | H8: 29 | I8: =IFERROR((H8-E8)/E8,"") -> -0.09375 | J8: =IFERROR((H8-G8)/G8,"") -> -0.09375 | K8: Uppskattat (mönster) | L8: Säsong
A9: FRU-03 | B9: Frukt & bär | C9: Jordgubbar | D9: kr/kg | E9: 75 | F9: 95 | G9: 85 | H9: 77 | I9: =IFERROR((H9-E9)/E9,"") -> 0.026666667 | J9: =IFERROR((H9-G9)/G9,"") -> -0.094117647 | K9: Uppskattat (mönster) | L9: Säsong
A10: FRU-04 | B10: Frukt & bär | C10: Blåbär | D10: kr/kg | E10: 100 | F10: 120 | G10: 60 | H10: 54 | I10: =IFERROR((H10-E10)/E10,"") -> -0.46 | J10: =IFERROR((H10-G10)/G10,"") -> -0.1 | K10: Uppskattat (mönster) | L10: Vilda/lokala klart billigare än odlat/import
A11: BAL-01 | B11: Baljväxter | C11: Gula ärtor | D11: kr/kg | E11: 30 | F11: 38 | G11: 37 | H11: 33 | I11: =IFERROR((H11-E11)/E11,"") -> 0.1 | J11: =IFERROR((H11-G11)/G11,"") -> -0.10810811 | K11: Uppskattat (mönster)
A12: BAL-02 | B12: Baljväxter | C12: Bruna bönor | D12: kr/kg | E12: 35 | F12: 44 | G12: 50 | H12: 45 | I12: =IFERROR((H12-E12)/E12,"") -> 0.28571429 | J12: =IFERROR((H12-G12)/G12,"") -> -0.1 | K12: Uppskattat (mönster) | L12: Ovanligt med svenskodlat
A13: BAL-03 | B13: Baljväxter | C13: Åkerböna | D13: kr/kg | E13: 40 | F13: 48 | G13: 42 | H13: 38 | I13: =IFERROR((H13-E13)/E13,"") -> -0.05 | J13: =IFERROR((H13-G13)/G13,"") -> -0.095238095 | K13: Uppskattat (mönster) | L13: Växande svensk nischodling
A14: SPA-01 | B14: Spannmål | C14: Havregryn | D14: kr/kg | E14: 17 | F14: 25 | G14: 35 | H14: 31 | I14: =IFERROR((H14-E14)/E14,"") -> 0.82352941 | J14: =IFERROR((H14-G14)/G14,"") -> -0.11428571 | K14: Verifierat | L14: Eko-påslag ca 44% verifierat
A15: SPA-02 | B15: Spannmål | C15: Rågmjöl | D15: kr/kg | E15: 20 | F15: 28 | G15: 30 | H15: 27 | I15: =IFERROR((H15-E15)/E15,"") -> 0.35 | J15: =IFERROR((H15-G15)/G15,"") -> -0.1 | K15: Uppskattat (mönster)
A16: SPA-03 | B16: Spannmål | C16: Vetemjöl | D16: kr/kg | E16: 12 | F16: 20 | G16: 25 | H16: 22 | I16: =IFERROR((H16-E16)/E16,"") -> 0.83333333 | J16: =IFERROR((H16-G16)/G16,"") -> -0.12 | K16: Uppskattat (mönster)
A17: SPA-04 | B17: Spannmål | C17: Korngryn | D17: kr/kg | E17: 17 | F17: 24 | G17: 25 | H17: 22 | I17: =IFERROR((H17-E17)/E17,"") -> 0.29411765 | J17: =IFERROR((H17-G17)/G17,"") -> -0.12 | K17: Uppskattat (mönster)
A18: KÖT-01 | B18: Kött | C18: Nötfärs | D18: kr/kg | E18: 105 | F18: 145 | G18: 120 | H18: 108 | I18: =IFERROR((H18-E18)/E18,"") -> 0.028571429 | J18: =IFERROR((H18-G18)/G18,"") -> -0.1 | K18: Verifierat
A19: KÖT-02 | B19: Kött | C19: Fläskkotlett | D19: kr/kg | E19: 110 | F19: 150 | G19: 125 | H19: 113 | I19: =IFERROR((H19-E19)/E19,"") -> 0.027272727 | J19: =IFERROR((H19-G19)/G19,"") -> -0.096 | K19: Uppskattat (mönster)
A20: KÖT-03 | B20: Kött | C20: Kycklingfilé | D20: kr/kg | E20: 115 | F20: 160 | G20: 155 | H20: 140 | I20: =IFERROR((H20-E20)/E20,"") -> 0.2173913 | J20: =IFERROR((H20-G20)/G20,"") -> -0.096774194 | K20: Uppskattat (mönster) | L20: Långsamväxande raser dyrare
A21: KÖT-04 | B21: Kött | C21: Lammkött | D21: kr/kg | E21: 185 | F21: 240 | G21: 215 | H21: 194 | I21: =IFERROR((H21-E21)/E21,"") -> 0.048648649 | J21: =IFERROR((H21-G21)/G21,"") -> -0.097674419 | K21: Uppskattat (mönster) | L21: Redan premium även i butik
A22: FIS-01 | B22: Fisk | C22: Odlad lax/regnbåge | D22: kr/kg | E22: 155 | F22: 190 | G22: 175 | H22: 158 | I22: =IFERROR((H22-E22)/E22,"") -> 0.019354839 | J22: =IFERROR((H22-G22)/G22,"") -> -0.097142857 | K22: Uppskattat (mönster)
A23: FIS-02 | B23: Fisk | C23: Strömming/sill | D23: kr/kg | E23: 65 | F23: 80 | G23: 55 | H23: 50 | I23: =IFERROR((H23-E23)/E23,"") -> -0.23076923 | J23: =IFERROR((H23-G23)/G23,"") -> -0.090909091 | K23: Uppskattat (mönster) | L23: Ofta billigare från lokal fiskare i säsong
A24: FIS-03 | B24: Fisk | C24: Gös/abborre | D24: kr/kg | E24: 300 | G24: 200 | H24: 180 | I24: =IFERROR((H24-E24)/E24,"") -> -0.4 | J24: =IFERROR((H24-G24)/G24,"") -> -0.1 | K24: Uppskattat (mönster) | L24: Knappt i vanlig butik, ingen bra eko-referens
A25: MEJ-01 | B25: Mejeri & ägg | C25: Mjölk | D25: kr/l | E25: 14 | F25: 17 | G25: 21 | H25: 19 | I25: =IFERROR((H25-E25)/E25,"") -> 0.35714286 | J25: =IFERROR((H25-G25)/G25,"") -> -0.095238095 | K25: Verifierat
A26: MEJ-02 | B26: Mejeri & ägg | C26: Smör | D26: kr/kg | E26: 132 | F26: 165 | G26: 175 | H26: 158 | I26: =IFERROR((H26-E26)/E26,"") -> 0.1969697 | J26: =IFERROR((H26-G26)/G26,"") -> -0.097142857 | K26: Verifierat
A27: MEJ-03 | B27: Mejeri & ägg | C27: Ägg | D27: kr/förp | E27: 40 | F27: 57 | G27: 47 | H27: 42 | I27: =IFERROR((H27-E27)/E27,"") -> 0.05 | J27: =IFERROR((H27-G27)/G27,"") -> -0.10638298 | K27: Verifierat | L27: Eko-påslag ca 42% verifierat
A28: MEJ-04 | B28: Mejeri & ägg | C28: Hushållsost | D28: kr/kg | E28: 125 | F28: 160 | G28: 185 | H28: 167 | I28: =IFERROR((H28-E28)/E28,"") -> 0.336 | J28: =IFERROR((H28-G28)/G28,"") -> -0.097297297 | K28: Verifierat
A29: NÖT-01 | B29: Nötter | C29: Valnötter | D29: kr/kg | E29: 150 | F29: 190 | H29: 155 | I29: =IFERROR((H29-E29)/E29,"") -> 0.033333333 | J29: =IFERROR((H29-G29)/G29,"") | K29: Uppskattat (mönster) | L29: Ren importvara, ingen meningsfull REKO-referens
A30: KRY-01 | B30: Kryddor/örter | C30: Persilja | D30: kr/knippe | E30: 18 | F30: 22 | G30: 15 | H30: 13 | I30: =IFERROR((H30-E30)/E30,"") -> -0.27777778 | J30: =IFERROR((H30-G30)/G30,"") -> -0.13333333 | K30: Uppskattat (mönster)
A31: KRY-02 | B31: Kryddor/örter | C31: Dill | D31: kr/knippe | E31: 18 | F31: 22 | G31: 15 | H31: 13 | I31: =IFERROR((H31-E31)/E31,"") -> -0.27777778 | J31: =IFERROR((H31-G31)/G31,"") -> -0.13333333 | K31: Uppskattat (mönster)
A32: KRY-03 | B32: Kryddor/örter | C32: Timjan | D32: kr/knippe | E32: 20 | F32: 25 | G32: 18 | H32: 16 | I32: =IFERROR((H32-E32)/E32,"") -> -0.2 | J32: =IFERROR((H32-G32)/G32,"") -> -0.11111111 | K32: Uppskattat (mönster)
A33: KRY-04 | B33: Kryddor/örter | C33: Svartpeppar | D33: kr/kg | E33: 200 | F33: 240 | H33: 210 | I33: =IFERROR((H33-E33)/E33,"") -> 0.05 | J33: =IFERROR((H33-G33)/G33,"") | K33: Uppskattat (mönster) | L33: Ren importvara
A34: OLJ-01 | B34: Matolja | C34: Rapsolja | D34: kr/l | E34: 58 | F34: 75 | G34: 85 | H34: 77 | I34: =IFERROR((H34-E34)/E34,"") -> 0.32758621 | J34: =IFERROR((H34-G34)/G34,"") -> -0.094117647 | K34: Verifierat
A35: OLJ-02 | B35: Matolja | C35: Olivolja | D35: kr/l | E35: 110 | F35: 140 | H35: 115 | I35: =IFERROR((H35-E35)/E35,"") -> 0.045454545 | J35: =IFERROR((H35-G35)/G35,"") | K35: Uppskattat (mönster) | L35: Ren importvara, ingen svensk variant
A36: VIN-01 | B36: Vinäger/syrat | C36: Äppelcidervinäger | D36: kr/l | E36: 55 | F36: 68 | G36: 65 | H36: 58 | I36: =IFERROR((H36-E36)/E36,"") -> 0.054545455 | J36: =IFERROR((H36-G36)/G36,"") -> -0.10769231 | K36: Uppskattat (mönster)
A37: VIN-02 | B37: Vinäger/syrat | C37: Surkål | D37: kr/kg | E37: 75 | F37: 90 | G37: 55 | H37: 48 | I37: =IFERROR((H37-E37)/E37,"") -> -0.36 | J37: =IFERROR((H37-G37)/G37,"") -> -0.12727273 | K37: Uppskattat (mönster) | L37: Billig att göra själv
A38: SVA-01 | B38: Svamp | C38: Champinjon | D38: kr/kg | E38: 50 | F38: 65 | G38: 60 | H38: 54 | I38: =IFERROR((H38-E38)/E38,"") -> 0.08 | J38: =IFERROR((H38-G38)/G38,"") -> -0.1 | K38: Uppskattat (mönster)
A39: SVA-02 | B39: Svamp | C39: Kantareller | D39: kr/kg | E39: 300 | F39: 340 | G39: 225 | H39: 200 | I39: =IFERROR((H39-E39)/E39,"") -> -0.33333333 | J39: =IFERROR((H39-G39)/G39,"") -> -0.11111111 | K39: Uppskattat (mönster) | L39: Säsongsberoende, självplock kan vara gratis
A40: SAL-01 | B40: Salt | C40: Havssalt | D40: kr/kg | E40: 220 | F40: 240 | G40: 200 | H40: 190 | I40: =IFERROR((H40-E40)/E40,"") -> -0.13636364 | J40: =IFERROR((H40-G40)/G40,"") -> -0.05 | K40: Uppskattat (mönster)
...

Sheet Recept
A1: Recept-ID | B1: Receptnamn | C1: Huvud-Produkt-ID | D1: Huvudingrediens (auto) | E1: Övriga ingredienser | F1: Portioner | G1: Tidsåtgång | H1: Anteckning
A2: REC-01 | B2: Rotfruktsgryta | C2: GRÖ-01 | D2: =IFERROR(INDEX(Skafferi!$C$2:$C$43,MATCH(C2,Skafferi!$A$2:$A$43,0)),"") -> Potatis | E2: Morot, gul lök, buljong | F2: 4 | G2: 45 min | H2: Bra fixa själv-recept, tål frysning
A3: REC-02 | B3: Havregrynsgröt med honung | C3: SPA-01 | D3: =IFERROR(INDEX(Skafferi!$C$2:$C$43,MATCH(C3,Skafferi!$A$2:$A$43,0)),"") -> Havregryn | E3: Mjölk, salt, SÖT-01 honung | F3: 2 | G3: 10 min | H3: Klassiker, snabb

Sheet Hemfabrikat
A1: Råvara Produkt-ID | B1: Råvara (auto) | C1: Blir till | D1: Metod (kort) | E1: Tidsåtgång | F1: Hållbarhet/lagring | G1: Anteckning
A2: SPA-01 | B2: =IFERROR(INDEX(Skafferi!$C$2:$C$43,MATCH(A2,Skafferi!$A$2:$A$43,0)),"") -> Havregryn | C2: Havremjölk | D2: Blötlägg, mixa, sila | E2: 15 min + kylning | F2: 3-4 dagar kylt | G2: Ger även havrepulp till bakning
A3: GRÖ-04 | B3: =IFERROR(INDEX(Skafferi!$C$2:$C$43,MATCH(A3,Skafferi!$A$2:$A$43,0)),"") -> Vitkål | C3: Surkål | D3: Strimla, salta, pressa, jäs | E3: 30 min + 1-4 veckors jäsning | F3: Flera månader kylt | G3: Bra fixa-själv-produkt kopplad till VIN-02

Sheet Om grödan
A1: Produkt-ID | B1: Produkt (auto) | C1: Säsong i Sverige | D1: Odlingsregion | E1: Näringsprofil (kort) | F1: Visste du att...
A2: GRÖ-01 | B2: =IFERROR(INDEX(Skafferi!$C$2:$C$43,MATCH(A2,Skafferi!$A$2:$A$43,0)),"") -> Potatis | C2: Aug-okt (skörd), lagringsbar året runt | D2: Hela landet, mest Skåne/Halland | E2: Kolhydrater, kalium, C-vitamin | F2: Potatis kom till Sverige på 1600-talet men blev allmän mat först på 1800-talet
A3: SVA-02 | B3: =IFERROR(INDEX(Skafferi!$C$2:$C$43,MATCH(A3,Skafferi!$A$2:$A$43,0)),"") -> Kantareller | C3: Jul-sep | D3: Mellansverige, blandskog | E3: Fiberrik, D-vitamin (soltorkad) | F3: Kantareller bildar mykorrhiza med träd och kan inte odlas kommersiellt i stor skala

Sheet Gårdsguiden – kandidater
A1: Namn | B1: Ort | C1: Län | D1: Gårdsguiden-kategori(er) | E1: Försäljningstyp | F1: Öppettider | G1: Skafferi-kategori (förslag) | H1: Dryckestagg (ej i skafferiet) | I1: Granska | J1: Källa | K1: Webb | L1: Telefon | M1: Epost | N1: Adress (berikad) | O1: Kohort årsvärde – kategori (kr) | P1: Kohort månadsvärde – kategori (kr)
A2: 3 Små Rum | B2: Göteborg | C2: Västra Götaland | D2: öl | E2: Provsmakning | F2: 16:00–23:00 | H2: öl | J2: https://www.gardsguiden.se/gardar
A3: AB Hembergs Trädgårdsprodukter | B3: Halmstad | C3: Halland | D3: grönsaker | F3: 07:00–12:00 | G3: Grönsaker | J3: https://www.gardsguiden.se/gardar | O3: ='Behovsmodell (75p)'!$B$62 -> 85559 | P3: =('Behovsmodell (75p)'!$B$62)/12 -> 7129.9167
A4: Abbes Mejeri | B4: Ronneby | C4: Blekinge | D4: mejeri | F4: 10:00–18:00 | G4: Mejeri & ägg | J4: https://www.gardsguiden.se/gardar | O4: ='Behovsmodell (75p)'!$B$68 -> 330040.65 | P4: =('Behovsmodell (75p)'!$B$68)/12 -> 27503.388
A5: Abraham Hill | C5: Skåne | D5: grönsaker | E5: Gårdsförsäljning | G5: Grönsaker | J5: https://www.gardsguiden.se/gardar | O5: ='Behovsmodell (75p)'!$B$62 -> 85559 | P5: =('Behovsmodell (75p)'!$B$62)/12 -> 7129.9167
A6: Adelsåsen Gårdsbutik | C6: Västra Götaland | E6: Gårdsförsäljning | F6: Stängt idag | J6: https://www.gardsguiden.se/gardar
A7: Adolfsnäs Handelsträdgård | B7: Vadstena | C7: Östergötland | D7: grönsaker | E7: Gårdsförsäljning | F7: 10:00–17:00 | G7: Grönsaker | J7: https://www.gardsguiden.se/gardar | K7: adolfsnas.se | N7: utanför Vadstena | O7: ='Behovsmodell (75p)'!$B$62 -> 85559 | P7: =('Behovsmodell (75p)'!$B$62)/12 -> 7129.9167
A8: Aftonmora Friesians & Vingård | C8: Skåne | D8: vin | E8: Provsmakning | H8: vin | J8: https://www.gardsguiden.se/gardar
A9: Agetomta Gård | B9: Norrköping | C9: Östergötland | E9: Gårdsförsäljning | F9: Stängt idag | J9: https://www.gardsguiden.se/gardar | K9: agetomtagard.com
A10: Agnesbergs Gårdsbutik | C10: Västra Götaland | E10: Gårdsförsäljning | J10: https://www.gardsguiden.se/gardar | N10: Västerljung
A11: Ahlafors Bryggerier | C11: Västra Götaland | D11: öl | E11: Provsmakning | H11: öl | J11: https://www.gardsguiden.se/gardar
A12: Alboga Choklad | C12: Västra Götaland | D12: mejeri | F12: Stängt idag | G12: Mejeri & ägg | J12: https://www.gardsguiden.se/gardar | O12: ='Behovsmodell (75p)'!$B$68 -> 330040.65 | P12: =('Behovsmodell (75p)'!$B$68)/12 -> 27503.388
A13: Ale Kött AB | B13: Göteborg | C13: Västra Götaland | D13: kött | F13: 10:00–18:00 | G13: Kött | J13: https://www.gardsguiden.se/gardar | N13: Göteborgsvägen 219, Ale | O13: ='Behovsmodell (75p)'!$B$66 -> 206427.05 | P13: =('Behovsmodell (75p)'!$B$66)/12 -> 17202.254
A14: Alekärr Ekologiska Gård | B14: Ale | C14: Västra Götaland | E14: Gårdsförsäljning | J14: https://www.gardsguiden.se/gardar
A15: Alliaria Bryggeri | B15: Västerås | C15: Västmanland | D15: öl | E15: Provsmakning | F15: Stängt idag | H15: öl | J15: https://www.gardsguiden.se/gardar
A16: Almnäs Bruk - Ysteri och Gårdsförsäljning: Självbetjäning | B16: Hjo | C16: Västra Götaland | E16: Gårdsförsäljning | I16: möjlig sammanslagning av två poster | J16: https://www.gardsguiden.se/gardar
A17: Almviks Mathantverk (Butiken) | C17: Östergötland | J17: https://www.gardsguiden.se/gardar
A18: Alsike trädgård | B18: Knivsta | C18: Uppsala | D18: grönsaker | E18: Gårdsförsäljning | G18: Grönsaker | J18: https://www.gardsguiden.se/gardar | K18: alsiketradgard.se | L18: 0700-45 37 80 | M18: kundtjanst@alsiketradgard.se | N18: Alsike Prästgård, 741 92 Knivsta | O18: ='Behovsmodell (75p)'!$B$62 -> 85559 | P18: =('Behovsmodell (75p)'!$B$62)/12 -> 7129.9167
A19: Alskute Farm & Brewery AB | C19: Gotland | D19: öl | E19: Provsmakning | H19: öl | J19: https://www.gardsguiden.se/gardar
A20: Andréns Bageri Sturkö | C20: Blekinge | D20: bakat | E20: Gårdsförsäljning; Provsmakning | F20: Stängt idag | G20: Bröd | J20: https://www.gardsguiden.se/gardar | O20: ='Behovsmodell (75p)'!$B$76 -> 111099 | P20: =('Behovsmodell (75p)'!$B$76)/12 -> 9258.25
A21: Angelikas Gård | C21: Skåne | E21: Gårdsförsäljning | F21: Stängt idag | J21: https://www.gardsguiden.se/gardar
A22: Annas Gårdsbutik och Mejeri | C22: Blekinge | D22: mejeri | E22: Gårdsförsäljning | F22: 06:30–19:00 | G22: Mejeri & ägg | J22: https://www.gardsguiden.se/gardar | K22: annaslantdrommar.se | L22: 070-533 73 93 | N22: Småskolevägen 8, 388 94 Vassmolösa | O22: ='Behovsmodell (75p)'!$B$68 -> 330040.65 | P22: =('Behovsmodell (75p)'!$B$68)/12 -> 27503.388
A23: Annas Gårdsbutik och Mejeri | C23: Kalmar | D23: mejeri | E23: Gårdsförsäljning | F23: 06:30–19:00 | G23: Mejeri & ägg | J23: https://www.gardsguiden.se/gardar | K23: annaslantdrommar.se | L23: 070-533 73 93 | N23: Småskolevägen 8, 388 94 Vassmolösa | O23: ='Behovsmodell (75p)'!$B$68 -> 330040.65 | P23: =('Behovsmodell (75p)'!$B$68)/12 -> 27503.388
A24: Annebergs Gård | B24: Varberg | C24: Halland | D24: vin | E24: Provsmakning | H24: vin | J24: https://www.gardsguiden.se/gardar | N24: Västerljung
A25: Annebergs Vingård | B25: Varberg | C25: Halland | D25: vin | E25: Provsmakning | H25: vin | J25: https://www.gardsguiden.se/gardar
A26: Annedals Gård | B26: Vellinge | C26: Skåne | E26: Gårdsförsäljning | F26: 13:00–18:00 | J26: https://www.gardsguiden.se/gardar
A27: Arentorps Bärodling AB | B27: Vara | C27: Västra Götaland | D27: grönsaker | E27: Gårdsförsäljning | G27: Grönsaker | J27: https://www.gardsguiden.se/gardar | O27: ='Behovsmodell (75p)'!$B$62 -> 85559 | P27: =('Behovsmodell (75p)'!$B$62)/12 -> 7129.9167
A28: Arkadien Mat & trädgård | B28: Gnesta | C28: Södermanland | D28: grönsaker | E28: Gårdsförsäljning; Provsmakning | G28: Grönsaker | J28: https://www.gardsguiden.se/gardar | O28: ='Behovsmodell (75p)'!$B$62 -> 85559 | P28: =('Behovsmodell (75p)'!$B$62)/12 -> 7129.9167
A29: Arla Foods | B29: Kalmar | C29: Kalmar | D29: mejeri | F29: 07:00–16:00 | G29: Mejeri & ägg | J29: https://www.gardsguiden.se/gardar | O29: ='Behovsmodell (75p)'!$B$68 -> 330040.65 | P29: =('Behovsmodell (75p)'!$B$68)/12 -> 27503.388
A30: Arla Kalmar Mejeri - Ostlager | B30: Kalmar | C30: Kalmar | D30: mejeri | F30: 06:00–16:00 | G30: Mejeri & ägg | J30: https://www.gardsguiden.se/gardar | O30: ='Behovsmodell (75p)'!$B$68 -> 330040.65 | P30: =('Behovsmodell (75p)'!$B$68)/12 -> 27503.388
A31: Aschebergsgatans Ost & Delikatesser | B31: Göteborg | C31: Västra Götaland | D31: mejeri | F31: 10:00–18:00 | G31: Mejeri & ägg | J31: https://www.gardsguiden.se/gardar | K31: aschebergsgatansost.se | L31: 031-16 77 72 | N31: Aschebergsgatan 36, 411 33 Göteborg | O31: ='Behovsmodell (75p)'!$B$68 -> 330040.65 | P31: =('Behovsmodell (75p)'!$B$68)/12 -> 27503.388
A32: Asketorps Gård | B32: Skövde | C32: Västra Götaland | E32: Gårdsförsäljning | F32: 06:00–19:00 | J32: https://www.gardsguiden.se/gardar
A33: Asketorps Gård | C33: Östergötland | F33: 06:00–19:00 | J33: https://www.gardsguiden.se/gardar
A34: Aspö gård | B34: Skövde | C34: Västra Götaland | E34: Gårdsförsäljning; Provsmakning | F34: 10:00–17:00 | J34: https://www.gardsguiden.se/gardar
A35: Aspö mad vin & café | C35: Blekinge | D35: vin | E35: Gårdsförsäljning; Provsmakning | F35: Stängt idag | H35: vin | J35: https://www.gardsguiden.se/gardar
A36: Assarsson Trädgård AB | B36: Motala | C36: Östergötland | D36: grönsaker | E36: Gårdsförsäljning | F36: 08:00–18:00 | G36: Grönsaker | J36: https://www.gardsguiden.se/gardar | O36: ='Behovsmodell (75p)'!$B$62 -> 85559 | P36: =('Behovsmodell (75p)'!$B$62)/12 -> 7129.9167
A37: Ást Bryggeri AB | C37: Västra Götaland | D37: öl | E37: Provsmakning | H37: öl | J37: https://www.gardsguiden.se/gardar
A38: Ateljé Leja, Gamla Bryggeriet i Weinge anno 1869 | B38: Laholm | C38: Halland | D38: öl | E38: Provsmakning | H38: öl | J38: https://www.gardsguiden.se/gardar
A39: Attanäs Gård | C39: Blekinge | E39: Gårdsförsäljning | F39: 11:00–18:00 | J39: https://www.gardsguiden.se/gardar
A40: Aviatören restaurang, café och mathantverk | B40: Linköping | C40: Östergötland | E40: Gårdsförsäljning; Provsmakning | F40: 10:00–17:00 | J40: https://www.gardsguiden.se/gardar
...

Sheet Kontaktberikade producenter
A1: Namn | B1: Ort | C1: Län | D1: Webb | E1: Telefon | F1: Epost | G1: Adress | H1: Källa | I1: Anmärkning | J1: Skafferi-kategori (matchad) | K1: Kohort årsvärde – kategori (kr) | L1: Kohort månadsvärde – kategori (kr)
A2: Gunnarshögs Gård | B2: Hammenhög | C2: Skåne | D2: gunnarshog.se | E2: 0414-320 03 | F2: info@gunnarshog.se | G2: Vallbyvägen 90, 276 56 Hammenhög | H2: Gårdens webbplats; hitta.se
A3: Kiviks Musteri | B3: Kivik | C3: Skåne | D3: kiviksmusteri.se | E3: 0414-719 00 | F3: info@kiviksmusteri.se | G3: Karakåsvägen 45, 277 35 Kivik | H3: Gårdens webbplats
A4: Ängavallens Gård/Gårdsbutik | B4: Vellinge | C4: Skåne | D4: angavallen.se | E4: 040-42 32 50 | F4: angavallen@angavallen.se | G4: Ängavallens väg 17-9, 235 91 Vellinge | H4: Gårdens webbplats
A5: Wapnö Gårdsbutik | B5: Halmstad | C5: Halland | D5: wapno.se | E5: 035-299 03 61 | F5: gardsbutik@wapno.se | G5: Wapnö Gård 215, 305 91 Halmstad | H5: Gårdens webbplats; Facebook
A6: Ästad Vingård | B6: Varberg | C6: Halland | D6: astadvingard.se | E6: 0340-460 06 | F6: info@astadvingard.se | G6: Ästad 10, Varberg | H6: Bolagsfakta; gårdens webbplats
A7: Dalsspira Mejeri | B7: Färgelanda | C7: Västra Götaland | D7: dalsspira.se | E7: 0528-500 01 | F7: info@dalsspira.se | G7: Håbynvägen 6, 458 30 Färgelanda | H7: Gårdens webbplats; proff.se | J7: Mejeri & ägg | K7: ='Behovsmodell (75p)'!$B$68 -> 330040.65 | L7: =('Behovsmodell (75p)'!$B$68)/12 -> 27503.388
A8: Brunneby Musteri | B8: Borensberg | C8: Östergötland | D8: brunnebymusteri.se | E8: 0141-402 04 / 070-8300090 | F8: butiken@brunnebymusteri.se / info@brunnebymusteri.se | G8: Brunneby Gård, 591 77/590 28 Borensberg | H8: Gårdens webbplats
A9: Löt Gårdsmejeri AB | B9: Gammalkil, Linköping | C9: Östergötland | D9: lot-gardsmejeri.se | E9: 070-090 01 83 | F9: lot.gardsmejeri@telia.com | G9: Löt Ryttargården 1, 583/585/590 Vikingstad | H9: gardsbutiker.se; visitlinkoping.se | J9: Mejeri & ägg | K9: ='Behovsmodell (75p)'!$B$68 -> 330040.65 | L9: =('Behovsmodell (75p)'!$B$68)/12 -> 27503.388
A10: Jürss Mejeri | B10: Hälleforsnäs, Flen | C10: Södermanland | D10: jurssmejeri.se | E10: 0157-141 10 | F10: jurssmejeri@jurssmejeri.se | G10: Gjutmästarbacken 1, 648 31 Hälleforsnäs | H10: visitflen.se | J10: Mejeri & ägg | K10: ='Behovsmodell (75p)'!$B$68 -> 330040.65 | L10: =('Behovsmodell (75p)'!$B$68)/12 -> 27503.388
A11: Warbro Kvarn AB | B11: Sköldinge, Katrineholm | C11: Södermanland | D11: warbrokvarn.se | E11: 073-034 39 42 / 073-034 39 88 | F11: butiken@warbrokvarn.se | G11: Linds Gård 1, 641 99 Sköldinge | H11: Gårdens webbplats; allabolag
A12: Gröna Hagars Kött | B12: Salbohed/Krylbo, Sala | C12: Västmanland | D12: gronahagarskott.se | E12: 070-560 82 25 | G12: Fallängetorp 106, Krylbo | H12: klimatsmart.se; smakapavastmanland.se | I12: Kontakt via formulär
A13: Rosendals Trädgård | B13: Stockholm | C13: Stockholm | D13: rosendalstradgard.se | E13: 08-545 812 70 | G13: Rosendalsterrassen 12, 115 21 Stockholm | H13: allabolag; gårdens webbplats | J13: Grönsaker | K13: ='Behovsmodell (75p)'!$B$62 -> 85559 | L13: =('Behovsmodell (75p)'!$B$62)/12 -> 7129.9167
A14: Rö Gårdsmejeri | B14: Rö, Norrtälje | C14: Stockholm | D14: rogardsmejeri.se | G14: Rö, Norrtälje | H14: Gårdens webbplats; roslagen.se | I14: LÄNSKORRIGERING - gardsguiden angav Uppsala | J14: Mejeri & ägg | K14: ='Behovsmodell (75p)'!$B$68 -> 330040.65 | L14: =('Behovsmodell (75p)'!$B$68)/12 -> 27503.388
A15: Väddö Gårdsmejeri | B15: Väddö, Norrtälje | C15: Stockholm | D15: vaddogardsmejeri.se | E15: 0176-501 03 | F15: info@vaddogardsmejeri.se | G15: Hammarbyvägen 34, 764 91 Väddö | H15: roslagen.se; allabolag
A16: Alsike Trädgård | B16: Knivsta | C16: Uppsala | D16: alsiketradgard.se | E16: 0700-45 37 80 | F16: kundtjanst@alsiketradgard.se | G16: Alsike Prästgård, 741 92 Knivsta | H16: Gårdens webbplats; Facebook | J16: Grönsaker | K16: ='Behovsmodell (75p)'!$B$62 -> 85559 | L16: =('Behovsmodell (75p)'!$B$62)/12 -> 7129.9167
A17: Bergqvara Gård | B17: Växjö | C17: Kronoberg | D17: bergqvaragard.se | E17: 0470-669 14 / 0470-669 70 | F17: gabrielle@bergqvaragard.se | G17: Bergkvara Gård, 355 93 Växjö | H17: Gårdsguiden; gårdens webbplats
A18: Folaboda Musteri & Destilleri | B18: Urshult | C18: Kronoberg | D18: folaboda.com | E18: 070-722 32 45 / 070-268 19 05 | G18: Fålaboda 3, 362 95 Urshult | H18: allbiz; MAT-rundan | I18: Motstridiga telefonnummer/postnr - verifiera
A19: Bolmen Fisk AB | B19: Hamneda, Ljungby | C19: Kronoberg | D19: bolmenfisk.se | E19: 0372-501 80 | G19: Kronogården gamla tomt 1, 341 75 Hamneda | H19: allabolag; naturkartan; MAT-rundan | J19: Fisk | K19: ='Behovsmodell (75p)'!$B$67 -> 58231.2 | L19: =('Behovsmodell (75p)'!$B$67)/12 -> 4852.6
A20: Rudenstams Gårdsbutik & Kafé | B20: Huskvarna | C20: Jönköping | D20: rudenstam.se | E20: 036-330 05 10 / 036-33 00 500 | F20: info@rudenstam.se | G20: Rudu Gård 50, 561 92 Huskvarna | H20: naturkartan; allabolag | J20: Grönsaker | K20: ='Behovsmodell (75p)'!$B$62 -> 85559 | L20: =('Behovsmodell (75p)'!$B$62)/12 -> 7129.9167
A21: Barlingbo Bryggeri AB | B21: Visby | C21: Gotland | D21: barlingbobryggeri.se | E21: 0498-10 53 50 | F21: info@barlingbobryggeri.se | G21: Artillerigatan 9, 621 38 Visby | H21: Gårdsguiden; gårdens webbplats
A22: Kruse Gård | B22: Alva | C22: Gotland | D22: krusegard.se | E22: 073-614 29 70 | F22: emmyahlsten@gmail.com | G22: Alva Lilla Kruse 613, Gotland | H22: gotland.com
A23: Stafva Gårdsbutik (Sjaustrukocken) | B23: Barlingbo | C23: Gotland | D23: sjaustrukocken.se / stafva.se | E23: 0498-310 05 / 070-073 14 04 | F23: sjaustrukocken753@gmail.com | G23: Barlingbo Stafva 300, 621 78 Visby | H23: gotland.com; Yelp; subagent | I23: Motstridiga tel/postnr - verifiera
A24: Ölands Köksmejeri | B24: Mörbylånga, Öland | C24: Kalmar | D24: olandskoksmejeri.se | E24: 0709-54 20 33 | F24: christer@havsvik.se | G24: Alby 121, 386 62 Mörbylånga | H24: Gårdens webbplats; visitoland.com; kollamaten | J24: Mejeri & ägg | K24: ='Behovsmodell (75p)'!$B$68 -> 330040.65 | L24: =('Behovsmodell (75p)'!$B$68)/12 -> 27503.388
A25: Wirbladhs Gårdshandel | B25: Smedby, Kalmar | C25: Kalmar | D25: wirbladhs.se | E25: 0480-47 12 43 | F25: info@wirbladhs.se | G25: Ljungbyvägen 1, 394 70 Kalmar | H25: Gårdens webbplats; hitta.se
A26: Solmarka Gårdsbutik | B26: Vassmolösa | C26: Kalmar | D26: solmarka.se | E26: 0480-361 55 | G26: Arby 207, 388 94 Vassmolösa | H26: krav.se; gårdens webbplats
A27: Orranäs Gårdsmejeri | B27: Jämjö | C27: Blekinge | D27: orranasgardsmejeri.se | E27: 0455-525 40 / 0760-52 97 77 | F27: info@orranasgardsmejeri.se | G27: Orranäs 436, 373 75 Jämjö | H27: gardsbutiker.se; gårdens webbplats | J27: Mejeri & ägg | K27: ='Behovsmodell (75p)'!$B$68 -> 330040.65 | L27: =('Behovsmodell (75p)'!$B$68)/12 -> 27503.388
A28: Gäsene Mejeri Ostbutik | B28: Ljung, Herrljunga | C28: Västra Götaland | D28: gasenemejeri.se | E28: 0513-250 80 | G28: Alingsåsvägen 32, 524 41 Ljung | H28: gasenemejeri.se; hitta.se | J28: Mejeri & ägg | K28: ='Behovsmodell (75p)'!$B$68 -> 330040.65 | L28: =('Behovsmodell (75p)'!$B$68)/12 -> 27503.388
A29: Ale Kött AB | B29: Bohus, Ale | C29: Västra Götaland | G29: Göteborgsvägen 219, Ale | H29: hitta.se; wheree.com | I29: Ev. charkbutik ej primärproducent - verifiera | J29: Kött | K29: ='Behovsmodell (75p)'!$B$66 -> 206427.05 | L29: =('Behovsmodell (75p)'!$B$66)/12 -> 17202.254
A30: Aschebergsgatans Ost & Delikatesser | B30: Göteborg | C30: Västra Götaland | D30: aschebergsgatansost.se | E30: 031-16 77 72 | G30: Aschebergsgatan 36, 411 33 Göteborg | H30: betyg.se; cylex.se | I30: Ej primärproducent - exkludera | J30: Mejeri & ägg | K30: ='Behovsmodell (75p)'!$B$68 -> 330040.65 | L30: =('Behovsmodell (75p)'!$B$68)/12 -> 27503.388
A31: Skattegårdens Lantost | B31: Sollebrunn, Magra | C31: Västra Götaland | D31: lantost.com | E31: 0322-430 03 | F31: info@lantost.com | G31: Höggärdetvägen 2, 441 74 Sollebrunn | H31: vastsverige.com; lantost.com | J31: Mejeri & ägg | K31: ='Behovsmodell (75p)'!$B$68 -> 330040.65 | L31: =('Behovsmodell (75p)'!$B$68)/12 -> 27503.388
A32: Kråkarps Gårdsmejeri | B32: Borgstena, Borås | C32: Västra Götaland | D32: krakarpsmejeri.se | E32: 070-939 69 86 | F32: elinor.krakarp@gmail.com | G32: Kråkarp 11, 513 97 Borgstena | H32: krakarpsmejeri.se; lokalproducerativast.se | J32: Mejeri & ägg | K32: ='Behovsmodell (75p)'!$B$68 -> 330040.65 | L32: =('Behovsmodell (75p)'!$B$68)/12 -> 27503.388
A33: Naturgården Västkött AB | B33: Vallda | C33: Västra Götaland | D33: naturgarden.se | E33: 031-52 28 32 | G33: Bröndomevägen 170, 434 79 Vallda | H33: naturgarden.se; allabolag | I33: Ligger i Halland - gränsfall | J33: Kött | K33: ='Behovsmodell (75p)'!$B$66 -> 206427.05 | L33: =('Behovsmodell (75p)'!$B$66)/12 -> 17202.254
A34: Slakthusets Köttbod | B34: Göteborg, Olskroken | C34: Västra Götaland | D34: slakthusetskottbod.se | E34: 073-514 10 11 | G34: Borgaregatan 19, Göteborg | H34: slakthusetskottbod.se; bolagsfakta | I34: Köper in kött - gränsfall | J34: Kött | K34: ='Behovsmodell (75p)'!$B$66 -> 206427.05 | L34: =('Behovsmodell (75p)'!$B$66)/12 -> 17202.254
A35: Vikaryds Köttbod | B35: Alingsås | C35: Västra Götaland | D35: vikaryd.com | E35: 0322-710 15 | F35: info@vikaryd.com | G35: Vikarydsvägen 5, 441 91 Alingsås | H35: vikaryd.com; lokalproducerativast.se | J35: Kött | K35: ='Behovsmodell (75p)'!$B$66 -> 206427.05 | L35: =('Behovsmodell (75p)'!$B$66)/12 -> 17202.254
A36: Ehrenhofers Lamm & Vilt | B36: Lödöse | C36: Västra Götaland | D36: ehrenhofers.se | E36: 0520-657 67 | G36: Högås 274, 463 71 Lödöse | H36: ehrenhofers.se; lokalproducerativast.se
A37: Sommarhagens Gårdsmejeri | B37: Nol, Ale | C37: Västra Götaland | D37: sommarhagensgardsmejeri.se | E37: 076-231 30 72 | F37: info@sommarhagensost.se | G37: Damma 420, 449 90 Nol | H37: egen webbplats
A38: Skålldals lilla Ekomejeri | B38: Kode | C38: Västra Götaland | D38: skalldalslillaekomejeri.se | E38: 070-345 41 64 | F38: skalldalslillaekomejeri@gmail.com | G38: Skålldal 340, 442 96 Kode | H38: egen webb; vastsverige.com | J38: Mejeri & ägg | K38: ='Behovsmodell (75p)'!$B$68 -> 330040.65 | L38: =('Behovsmodell (75p)'!$B$68)/12 -> 27503.388
A39: Lexby Gård | B39: Partille | C39: Västra Götaland | D39: lexbygard.se | E39: 070-544 66 97 | G39: Gamla Lexbyvägen 9, 433 31 Partille | H39: lexbygard.se; hitta.se | I39: Osäkert om aktiv gårdsbutik
A40: Limmareds Säteri | B40: Limmared | C40: Västra Götaland | D40: limmaredssateri.se | E40: 076-786 69 57 | F40: info@limmaredssateri.se | G40: Limmareds Säteri, 514 50 Limmared | H40: limmaredssateri.se
...
